Workbook

Sheet Call Log
A1: Junior Achievement — School Partnership Cold Call Tracker
A2: Call ID | B2: Date | C2: Caller Name | D2: Contact Name | E2: Title | F2: Organization | G2: City | H2: County | I2: Phone | J2: Email | K2: Categorical Grouping | L2: Has Open Space? | M2: Space (sq ft) | N2: Max Capacity | O2: Past Partnerships? | P2: Impact Assessment Rating | Q2: Outcome | R2: Stage | S2: Call Back? | T2: Notes / Next Steps
B3: 46083 | C3: Grant | F3: Nelsonville-York High School | G3: Nelsonville | H3: Athens County | I3: (740) 753-1737 | K3: 5 | Q3: Not Interested | R3: Cold
B4: 46083 | C4: Grant | F4: Chillicothe High School | G4: Chillicothe | H4: Ross County | I4: (740) 775-4250 | K4: 4 | Q4: Not Interested | R4: Cold
B5: 46084 | C5: Luke | F5: Valley High School | G5: Lucasville | H5: Scioto County | I5: (740) 259-3115 | Q5: Call Back | R5: Cold | S5: No | T5: Left a voicemail with the principal. Worth calling back
B6: 46084 | C6: Luke | F6: Northwest High School | G6: McDermott | H6: Scioto County | I6: (740) 259-2366 | Q6: Call Back | R6: Cold | S6: No | T6: Left a voicemail with the principal. Worth calling back
B7: 46084 | C7: Grant | D7: Scott McCallum | F7: Mt. Logan Early Childhood Center | G7: Chillicothe | H7: Ross County | I7: (740)773-2638 | J7: mccallum@horizonview.net, hers is kmccallum@adena.org | K7: 4 | L7: Yes | N7: 389 | Q7: Interested | R7: Assessing Fit | S7: Emailed | T7: CONTACT: LATER Transfered to district office, They have a club, connect 4 club, students that dont have means but want to go to college
A8: =IF(B8>"",ROW()-3,"") | B8: 46084 | C8: Grant | F8: Unioto Elementary | G8: Chillicothe | H8: Ross County | I8: (740)773-4103 | K8: 4 | L8: No | Q8: Voicemail | T8: Left a voicemail. Worth calling back
A9: =IF(B9>"",ROW()-3,"") | B9: 46084 | C9: Grant | F9: Addaville Elementary School | G9: Gallipolis | H9: Gallia County | I9: (740)367-7283 | K9: 4 | Q9: Voicemail | R9: Cold | T9: Left a voicemail, worth calling back
A10: =IF(B10>"",ROW()-3,"") | B10: 46084 | C10: Grant | F10: Buckeye Hills Career Center | G10: Rio Grande | H10: Gallia County | I10: (740)245-5334 | K10: 4 | Q10: Voicemail | R10: Cold | T10: Left a voicemail, worth calling back
A11: =IF(B11>"",ROW()-3,"") | B11: 46086 | C11: Grant | F11: Steubenville High School | G11: Steubenville | H11: Jefferson County | I11: (740)282-9741 | K11: 5 | Q11: Not Interested | R11: Cold
A12: =IF(B12>"",ROW()-3,"") | B12: 46086 | C12: Grant | F12: Barnesville Middle School | G12: Barnesville | H12: Belmont County | I12: (740)425-3116 | K12: 5 | L12: Yes | Q12: Voicemail | R12: Cold
A13: =IF(B13>"",ROW()-3,"") | B13: 46086 | C13: Grant | F13: Indian Creek High School | G13: Wintersville | H13: Jefferson County | I13: (740)264-1163 | K13: 5 | Q13: No Answer
A14: =IF(B14>"",ROW()-3,"") | B14: 46086 | C14: Grant | D14: Garrett Davis | F14: Marietta Elementary School | G14: Marietta | H14: Washington County | I14: (740)374-6530 | K14: 3 | N14: 700 | O14: Unsure | T14: Left voicemail with the principal, worth calling back
B15: 46086 | C15: Mac | F15: Morgan High School | G15: McConnelsville | H15: Morgan County | I15: (740)962-2944 | K15: 3 | Q15: Voicemail | R15: Cold | T15: Left voicemail with the principal, worth calling back
B16: 46086 | C16: Grant | D16: Chad Grove | E16: Principal | F16: Logan High School | G16: Logan | H16: Hocking County | I16: (740)385-2069 | K16: 3 | Q16: Voicemail | R16: Cold | T16: Left voicemail with the principal, worth calling back
B17: 46086 | C17: Grant | E17: Principal | F17: Jasper Elementary School | G17: Piketon | H17: Pike County | I17: (740) 289-2425 | K17: 4 | Q17: Voicemail | R17: Cold | T17: Left voicemail with the principal, worth calling back
B18: 46086 | C18: Grant | E18: Secretary | F18: Oak Hill Elementary | G18: Oak Hill | H18: Jackson County | I18: (740) 682-7096 | K18: 4 | L18: Yes | Q18: Call Back | S18: No | T18: Spoke with secretary, she promised to call me back
B19: 46087 | C19: Lexi | D19: Kimberly | E19: Principal | F19: Washinton Elementary | G19: Gallpolis | H19: Galia County | I19: 740-446-3213 | K19: 4 | Q19: Voicemail | R19: Cold
B20: 46087 | C20: Lexi | D20: Kristy | E20: Secretary | F20: Jackson Northview Elementary School | G20: Jackson City | H20: Jackson County | I20: (740) 286-2390 | K20: 4 | Q20: Call Back | R20: Cold | S20: No | T20: Secretary, gave number to principal
B21: 46087 | C21: Luke | D21: Emma | F21: Caldwell Elementary School | G21: Caldwell | H21: Noble County | I21: 740-732-4614 | J21: emarshall@caldwell.k12.oh.us | K21: 5 | Q21: Interested | R21: Contacted | S21: No | T21: Email Principle about details of program
B22: 46087 | C22: Grant | E22: Secretary | F22: Martins Ferry High School | G22: Martins Ferry | H22: Belmont County | I22: (740)633-0684 | K22: 5 | Q22: Call Back | R22: Contacted | S22: No | T22: I spoke to the receptionist who was new and couldn't figure out how to transfer me, she gave the assistant principal my #. See seemed earnest, great to call back if I'm not contacted first
B23: 46087 | C23: Grant | D23: Audrey Carpenter | E23: Supervisor | F23: Cambridge Primary School | G23: Cambridge | H23: Guernsey County | I23: (740)439-7547 | K23: 5 | Q23: Voicemail | R23: Contacted | T23: Left voicemail with supervisor.
B24: 46087 | C24: Grant | F24: trimble high school | G24: Glouster | H24: Athens County | I24: (740)767-3434 | K24: 3 | Q24: No Answer | R24: Cold | T24: No response, dont call back
B25: 46087 | C25: Grant | F25: Central Elementary | G25: McArthur | H25: Vinton County | I25: (740)596-4155 | K25: 3 | Q25: No Answer | R25: Cold | T25: No response, dont call back
B26: 46087 | C26: Grant | F26: Eastern High School | G26: Reedsville | H26: Meigs County | I26: (740)985-3329 | K26: 3 | Q26: Voicemail | R26: Contacted | T26: Left message with principal, also called district office --> Routed to superintendent, I left a message with both, i think it is worth a callback
B27: 46087 | C27: Grant | D27: Bob Byer, Jeniffer Reed | E27: Principal, Secretary | F27: Cambridge High School | G27: Cambridge | H27: Guernsey County | I27: (740)435-1100 | K27: 5 | Q27: Interested | R27: Contacted | T27: Both away from desk: left message with both
B28: 46087 | C28: Grant | F28: Woodsfield Elementary School | G28: Woodsfield | H28: Monroe County | I28: (740)472-0953 | K28: 5 | Q28: Not Interested | R28: Cold | T28: Not interested
B29: 46087 | C29: Grant | F29: River Elementary School | G29: Hannibal | H29: Monroe County | I29: (740)483-1358 | K29: 5 | Q29: Voicemail | R29: Cold | T29: intiially uninterested, but I called their district instead of secretary and ended up giving number to superintendent
B30: 46087 | C30: Grant | D30: Lavanna | E30: Secretary to Superindendent | F30: federal hocking middle school | G30: Stewart | H30: Athens County | I30: (740)662-6691 | J30: email: llaughing@fhlancers.com | K30: 3 | Q30: Interested | R30: Assessing Fit | S30: Emailed | T30: Email lavana with information about the program. They seemed insterested, but were concerned about the price potentially. She says if its for the students, they can make an exception
B31: 46090 | C31: Lexi | D31: Jessie | E31: Secretary to District Office | F31: Glenford Elemenary | G31: Glenford | H31: Perry County | I31: 740-743-1303 (district office) | K31: 2 | Q31: Call Back | R31: Cold | S31: No | T31: Call back in a week and ask to speak to Mrs. Gussler
A32: =IF(B32>"",ROW()-3,"") | B32: 46090 | C32: Lexi | D32: Mrs. Canon | E32: Principal | F32: Junction City Elementary School | G32: Junction City | H32: Perry County | I32: (740)987-3751 | K32: 2 | Q32: Voicemail | R32: Cold | T32: Left voicemail with principal
A33: =IF(B33>"",ROW()-3,"") | B33: 46090 | C33: Lexi | D33: Amy | E33: Secretary | F33: Millcreek Elementary School | G33: Corning | H33: Perry County | I33: (740)721-0522 | K33: 2 | Q33: Voicemail | R33: Cold | T33: Left voicemail with principal
A34: =IF(B34>"",ROW()-3,"") | B34: 46090 | C34: Grant | D34: Lucas Parsons | E34: Principal | F34: Buckeye Local High School | G34: Rayland | H34: Jefferson County | I34: (740)859-2196 | K34: 5 | Q34: Voicemail | R34: Cold | T34: Left voicemail with principal
A35: =IF(B35>"",ROW()-3,"") | B35: 46091 | C35: Grant | E35: Principal Secretary | F35: River Valley High School | G35: Bidwell | H35: Gallia County | I35: (740)446-2926 | J35: Rochelle Halley: 7403799085, extension 10026 | K35: 4 | Q35: Call Back | R35: Assessing Fit | S35: No | T35: Identified their Rochelle Halley: Curriculum Administator 7403799085, extension 10026. Rochelle did not answer, she was away from phone, definitelly call back
A36: =IF(B36>"",ROW()-3,"") | B36: 46091 | C36: Grant | E36: Secretary | F36: Jackson High School | G36: Jackson | H36: Jackson County | I36: (740) 286-7575 | K36: 4 | Q36: Call Back | R36: Cold | S36: No | T36: Worth Call back: Secretary is very nice, seems excited to help, but both Principals in meetings, left voicemail with guidance councellor to guidance councellor
A37: =IF(B37>"",ROW()-3,"") | B37: 46091 | C37: Grant | E37: Elementary and Middle School Principals, Guidance Counsellor | F37: Buckeye Trail Elementary | G37: Lore City | H37: Guernsey County | I37: (740)489-5100 | K37: 5 | Q37: Voicemail | R37: Cold | T37: Left voicemail with Elementary principal, Middle School Principal, Guidance Counsellor
A38: =IF(B38>"",ROW()-3,"") | B38: 46091 | C38: Grant | D38: Sue Ferrelli | E38: Curriculum Director | F38: Anna Marie Ayers Elementary School | G38: Martins Ferry | H38: Belmont County | I38: (740)633-1732 | J38: sueferrelli@mfcsd.org | K38: 5 | Q38: Interested | R38: Partnership Discussion | S38: Emailed | T38: Spoke to curriculum director, she indicated an interest in the program, specifically asking for more information, so that she can pass it on back to the superintendent. She had some questions which I think the survey would help adress
A39: =IF(B39>"",ROW()-3,"") | B39: 46091 | C39: Grant | F39: Shenandoah Elementary School | G39: Sarahsville | H39: Noble County | I39: (740)732-5661 | K39: 5 | Q39: Voicemail | R39: Cold | T39: Voicemail with principal
A40: =IF(B40>"",ROW()-3,"") | B40: 46091 | C40: Grant | F40: coolville elementary school | G40: Coolville | H40: Athens County | I40: (740)667-3121 | K40: 3 | Q40: No Answer | R40: Cold | S40: No | T40: No response, not worth callback
...

Sheet Script Reference
A1: Revised Script for New Cold Callers
A3: Context | C3: Added Explanation
A4: Greeting | B4: Hi, how are you doing? My name _________.
A5: Introduction | B5: I am working for JACO, which is one of the largest non-profit programs in the nation, specifically focused on offering financial readiness and career skills to young children.
A6: How it Works | B6: JA hosts events using mobile learning units — collaborating with schools and public spaces (free of charge to schools) to act as a hands-on learning experience for young people.
A8: Why Statement
A9: Why Statement | B9: Junior Achievement currently only services Central Ohio, but hopes to expand to new areas.
A10: Purpose | B10: I just wanted to call today to survey interest or willingness to collaborate with Junior Achievement. Do you have anyone* I can talk to today? | C10: *They will likely direct you as needed, but if they ask, say principals, district office, or curriculum director in that order
A11: JA Reach | B11: JA reaches over 4.4 million students per year in 176,714 classrooms and after-school locations across all 50 states. | C11: You can use this type of information to supplement JACOs value, to highlight their credibility
A13: Impact/Measureable Interest Assessment | C13: Try to ask these if possible, but we take note of how receptive respondants are to answering them
A14: Impact Assesment | B14: I understand that you have just recieved a lot of information, but do you have an idea of how impactful would such a program might be to your (school/students), on a Scale of 1-5?
A15: Measureable Interest | B15: On the same note, do you have an idea of how initially interested you may be in collaborating with a program like Junior Achievement
A17: QUALIFYING QUESTIONS — SPACE (Log answers in spreadsheet) | C17: You very often may not reach these questions, depending on receptiveness or availabilty of respondants
A18: Space Exists? | B18: Does your school/church/organization have an auditorium, gym, or open space?
A19: Size | B19: Is the space at least 57 by 38 feet, or about 2,166 square feet?
A20: Capacity | B20: Do you know the maximum capacity of this space? We're ideally looking for around 150 people.
A21: Past Events | B21: Has your school partnered with organizations or hosted events in this space in the past?
A23: HOSTING / PARTNERSHIP ASK — Choose One Approach
A24: Option C (Casual) | B24: We're a nonprofit working to directly support students. Our goal is to make this as accessible as possible for students and partners alike. If we were to bring this service to your community, do you think there could be flexibility around hosting costs?

Sheet Interest per Group

Sheet Summary
A1: Call Summary Dashboard — JA Partnership Drive
A3: Call Outcome | B3: Count | D3: Partnership Stage | E3: Count | G3: Space Qualification | H3: Count
A4: Interested | B4: =COUNTIF('Call Log'!Q:Q,"Interested") -> 6 | D4: Cold | E4: =COUNTIF('Call Log'!R:R,"Cold") -> 43 | G4: Space: Yes | H4: =COUNTIF('Call Log'!L:L,"Yes") -> 3
A5: Not Interested | B5: =COUNTIF('Call Log'!Q:Q,"Not Interested") -> 6 | D5: Contacted | E5: =COUNTIF('Call Log'!R:R,"Contacted") -> 6 | G5: Space: No | H5: =COUNTIF('Call Log'!L:L,"No") -> 1
A6: Call Back | B6: =COUNTIF('Call Log'!Q:Q,"Call Back") -> 9 | D6: Assessing Fit | E6: =COUNTIF('Call Log'!R:R,"Assessing Fit") -> 3 | G6: Space: Unknown | H6: =COUNTIF('Call Log'!L:L,"Unknown") -> 0
A7: Voicemail | B7: =COUNTIF('Call Log'!Q:Q,"Voicemail") -> 35 | D7: Space Confirmed | E7: =COUNTIF('Call Log'!R:R,"Space Confirmed") -> 0 | G7: Past Partnerships | H7: =COUNTIF('Call Log'!O:O,"Yes") -> 0
A8: No Answer | B8: =COUNTIF('Call Log'!Q:Q,"No Answer") -> 7 | D8: Partnership Discussion | E8: =COUNTIF('Call Log'!R:R,"Partnership Discussion") -> 1
A9: Wrong Number | B9: =COUNTIF('Call Log'!Q:Q,"Wrong Number") -> 0 | D9: Committed | E9: =COUNTIF('Call Log'!R:R,"Committed") -> 0
A10: Do Not Contact | B10: =COUNTIF('Call Log'!Q:Q,"Do Not Contact") -> 0 | D10: Closed | E10: =COUNTIF('Call Log'!R:R,"Closed") -> 0
A11: Total Calls Logged | B11: =COUNTA('Call Log'!B3:B201) -> 64 | D11: Commit Rate | E11: =IFERROR(COUNTIF('Call Log'!R:R,"Committed")/COUNTA('Call Log'!B3:B201),0) -> 0

Sheet Sheet1
O18: 3 | P18: 5
O19: 5 | P19: 4
O22: 5 | P22: 4
O23: 5 | P23: 4
O24: 5 | P24: 4
O25: 5 | P25: 4
O26: 3 | P26: 5
O27: 3 | P27: 5
O28: 3 | P28: 5
O30: 4 | P30: 3
O31: 4 | P31: 3
O32: 5 | P32: 4
... O34: 5 | P34: 4
O35: 5 | P35: 4 | Y35: =COUNTIF('Call Log'!C:C, "Lexi") -> 5
O36: 3 | P36: 5 | Y36: =COUNTIF('Call Log'!C:C, "Grant") -> 52
O37: 3 | P37: 5 | Y37: =COUNTIF('Call Log'!C:C, "Luke") -> 5
O38: 3 | P38: 5 | Y38: =COUNTIF('Call Log'!C:C, "Mac") -> 1
O39: 4 | P39: 3 | Y39: =COUNTIF('Call Log'!C:C, "Aniket") -> 0
O40: 4 | P40: 3 | Y40: =COUNTIF('Call Log'!C:C, "Jigisha") -> 0
O41: 4 | P41: 3
O42: 3 | P42: 5
O43: 3 | P43: 5
O44: 3 | P44: 5
O45: 4 | P45: 3
O46: 2 | P46: 2
O47: 2 | P47: 2
O48: 2 | P48: 2
O49: 3 | P49: 5
O50: 5 | P50: 4
O51: 5 | P51: 4
O52: 3 | P52: 5
... O54: 3 | P54: 5
